Workbook

Sheet Tablero
B6: ZONA | C6: DETALLE | D6: RACIONES DIA | G6: TOTAL PUNTOS DE BAJADA*
D7: COMIDAS | E7: REFRIGERIOS | G7: CAPITAL | H7: INTERIOR | J7: TOTAL DEPENDIENTES *
C8: ACCION SOCIAL * | D8: ='PADRON CAP'!H346 -> 13875 | E8: ='PADRON CAP'!I346 -> 11708 | G8: =SUMPRODUCT(1/COUNTIF('PADRON CAP'!D3:'PADRON CAP'!D342,'PADRON CAP'!D3:'PADRON CAP'!D342)) -> 212 | H8: =SUMPRODUCT(1/COUNTIF('PADRON INTERIOR'!B3:'PADRON INTERIOR'!B257,'PADRON INTERIOR'!B3:'PADRON INTERIOR'!B257)) -> 133 | J8: CAPITAL | K8: INTERIOR
C9: MINORIDAD Y FAMILIA * | D9: ='PADRON CAP'!H347 -> 1450 | E9: ='PADRON CAP'!I347 -> 1910 | G9: TOTAL | H9: =+G8+H8 -> 345 | J9: =SUMPRODUCT(1/COUNTIF('PADRON CAP'!D3:'PADRON CAP'!D342,'PADRON CAP'!D3:'PADRON CAP'!D342)) -> 212 | K9: =SUMPRODUCT(1/COUNTIF('PADRON INTERIOR'!C3:'PADRON INTERIOR'!C257,'PADRON INTERIOR'!C3:'PADRON INTERIOR'!C257)) -> 167
C10: MINISTERIO DE JUSTICIA * | D10: ='PADRON CAP'!H348 -> 410 | E10: ='PADRON CAP'!I348 -> 345 | J10: TOTAL | K10: =+J9+K9 -> 379
C11: ACCION SOCIAL * | D11: ='PADRON INTERIOR'!I261 -> 4615 | E11: ='PADRON INTERIOR'!J261 -> 7122
C12: MINORIDAD Y FAMILIA * | D12: ='PADRON INTERIOR'!I262 -> 2476 | E12: ='PADRON INTERIOR'!J262 -> 4805
C13: MINISTERIO DE JUSTICIA * | D13: ='PADRON INTERIOR'!I263 -> 85 | E13: ='PADRON INTERIOR'!J263 -> 145
B14: SUBTOTAL RAC. DIA PLAN 1 2026* | D14: =SUM(D8:D13) -> 22911 | E14: =SUM(E8:E13) -> 26035
C15: ASISTENCIA A LADRILLEROS | D15: ='PADRON CAP'!H349 -> 2365 | E15: ='PADRON CAP'!I349 -> 2250
C16: MOVIMIENTOS PASTORALES | D16: ='PADRON CAP'!H350 -> 0 | E16: ='PADRON CAP'!I350 -> 2400 | G16: CANTIDAD DE Centros de Distribución (Cabeceras) DE: | K16: CANTIDAD DE DEPENDIENTES (retiran de los puntos de distribución) por:
C17: MOVIMIENTOS SOCIALES | D17: ='PADRON CAP'!H351 -> 3950 | E17: ='PADRON CAP'!I351 -> 3153 | G17: ZONA | H17: REFRIGERIOS | I17: COMIDAS
B18: TOTAL RAC. DIA PLAN 1 2026 | D18: =+D14+D15+D16+D17 -> 29226 | E18: =+E14+E15+E16+E17 -> 33838 | G18: CAPITAL (1) | H18: {=SUM(--(FREQUENCY(IF('PADRON CAP'!I3:'PADRON CAP'!I342='PADRON CAP'!L1,MATCH('PADRON CAP'!D3:'PADRON CAP'!D342,'PADRON CAP'!D3:'PADRON CAP'!D342,0)),ROW('PADRON CAP'!D3:'PADRON CAP'!D342)-ROW('PADRON CAP'!D3)+1)>0))} -> 185 | I18: {=SUM(--(FREQUENCY(IF('PADRON CAP'!I3:'PADRON CAP'!I342='PADRON CAP'!M1,MATCH('PADRON CAP'!D3:'PADRON CAP'!D342,'PADRON CAP'!D3:'PADRON CAP'!D342,0)),ROW('PADRON CAP'!D3:'PADRON CAP'!D342)-ROW('PADRON CAP'!D3)+1)>0))} -> 155 | K18: ZONA | L18: REFRIGERIOS | M18: COMIDAS
G19: INTERIOR | H19: {=(SUM(--(FREQUENCY(IF('PADRON INTERIOR'!J3:'PADRON INTERIOR'!J257='PADRON INTERIOR'!M1,MATCH('PADRON INTERIOR'!B3:'PADRON INTERIOR'!B257,'PADRON INTERIOR'!B3:'PADRON INTERIOR'!B257,0)),ROW('PADRON INTERIOR'!B3:'PADRON INTERIOR'!B257)-ROW('PADRON INTERIOR'!B3)+1)>0)))} -> 119 | I19: {=SUM(--(FREQUENCY(IF('PADRON INTERIOR'!J3:'PADRON INTERIOR'!J257='PADRON INTERIOR'!N1,MATCH('PADRON INTERIOR'!B3:'PADRON INTERIOR'!B257,'PADRON INTERIOR'!B3:'PADRON INTERIOR'!B257,0)),ROW('PADRON INTERIOR'!B3:'PADRON INTERIOR'!B257)-ROW('PADRON INTERIOR'!B3)+1)>0))} -> 90 | K19: CAPITAL (1) | L19: =((COUNTIFS('PADRON CAP'!$I$3:$I$342,"REFRIGERIOS"))) -> 185 | M19: =((COUNTIFS('PADRON CAP'!$I$3:$I$2343,"comidas"))) -> 155
G20: TOTAL | H20: =+H18+H19 -> 304 | I20: =+I18+I19 -> 245 | K20: INTERIOR | L20: =(COUNTIFS('PADRON INTERIOR'!$J$3:$J$257,"REFRIGERIOS"))-'PADRON INTERIOR'!J273 -> 151 | M20: =(COUNTIFS('PADRON INTERIOR'!$J$3:$J$257,"COMIDAS"))-'PADRON INTERIOR'!I273 -> 104
K21: TOTAL | L21: =SUM(L19:L20) -> 336 | M21: =SUM(M19:M20) -> 259
D22: CAPITAL | E22: INTERIOR
C23: ACCION SOCIAL | D23: {=SUM(--(FREQUENCY(IF('PADRON CAP'!G3:'PADRON CAP'!G342='PADRON CAP'!D344,MATCH('PADRON CAP'!D3:'PADRON CAP'!D342,'PADRON CAP'!D3:'PADRON CAP'!D342,0)),ROW('PADRON CAP'!D3:'PADRON CAP'!D342)-ROW('PADRON CAP'!D3)+1)>0))} -> 153 | E23: 83
C24: MINORIDAD Y FAMILIA | D24: {=SUM(--(FREQUENCY(IF('PADRON CAP'!G3:'PADRON CAP'!G342='PADRON CAP'!D346,MATCH('PADRON CAP'!D3:'PADRON CAP'!D342,'PADRON CAP'!D4:'PADRON CAP'!D342,0)),ROW('PADRON CAP'!D3:'PADRON CAP'!D342)-ROW('PADRON CAP'!D3)+1)>0))} -> 25 | E24: 82
C25: MINSTERIO DE JUSTICIA | D25: {=SUM(--(FREQUENCY(IF('PADRON CAP'!G4:'PADRON CAP'!G343='PADRON CAP'!D349,MATCH('PADRON CAP'!D4:'PADRON CAP'!D343,'PADRON CAP'!D5:'PADRON CAP'!D343,0)),ROW('PADRON CAP'!D4:'PADRON CAP'!D343)-ROW('PADRON CAP'!D4)+1)>0))} -> 8 | E25: {=SUM(--(FREQUENCY(IF('PADRON INTERIOR'!I3:'PADRON INTERIOR'!I257='PADRON INTERIOR'!B261,MATCH('PADRON INTERIOR'!C3:'PADRON INTERIOR'!C257,'PADRON INTERIOR'!C3:'PADRON INTERIOR'!C257,0)),ROW('PADRON INTERIOR'!C3:'PADRON INTERIOR'!C257)-ROW('PADRON INTERIOR'!C3)+1)>0))} -> 3
C26: ASOC. LADRILLEROS (CAPITAL) | D26: {=SUM(--(FREQUENCY(IF('PADRON CAP'!G5:'PADRON CAP'!G344='PADRON CAP'!D345,MATCH('PADRON CAP'!D5:'PADRON CAP'!D344,'PADRON CAP'!D6:'PADRON CAP'!D344,0)),ROW('PADRON CAP'!D5:'PADRON CAP'!D344)-ROW('PADRON CAP'!D5)+1)>0))} -> 17
C27: MOVIMIENTOS PASTORALES | D27: {=SUM(--(FREQUENCY(IF('PADRON CAP'!G6:'PADRON CAP'!G345='PADRON CAP'!D347,MATCH('PADRON CAP'!D6:'PADRON CAP'!D345,'PADRON CAP'!D7:'PADRON CAP'!D345,0)),ROW('PADRON CAP'!D6:'PADRON CAP'!D345)-ROW('PADRON CAP'!D6)+1)>0))} -> 2
C28: MOVIMIENTOS SOCIALES | D28: {=SUM(--(FREQUENCY(IF('PADRON CAP'!G7:'PADRON CAP'!G346='PADRON CAP'!D348,MATCH('PADRON CAP'!D7:'PADRON CAP'!D346,'PADRON CAP'!D8:'PADRON CAP'!D346,0)),ROW('PADRON CAP'!D7:'PADRON CAP'!D346)-ROW('PADRON CAP'!D7)+1)>0))} -> 7
D29: =SUM(D23:D28) -> 212 | E29: =SUM(E23:E28) -> 168
D30: =+D29+E29 -> 380
D32: =+D33/D36 -> 0.77376823
C33: valor | D33: =+D18 -> 29226
C34: Plan | D34: =+D18 -> 29226 | H34: =+H35/H38 -> 0.89915765
C35: Saldo | D35: =+D36-D34 -> 8545 | G35: valor | H35: =+E18 -> 33838
C36: Licitado | D36: 37771 | G36: Plan | H36: =+E18 -> 33838
G37: Saldo | H37: =+H38-H36 -> 3795
C38: inicio | D38: =+D33-D39/1 -> 27726 | G38: Licitado | H38: 37633
C39: ancho | D39: 1500
C40: fin | D40: =SUM(D34:D36)-D38-D39 -> 46316 | G40: inicio | H40: =+H35-H41/1 -> 32338
G41: ancho | H41: 1500
G42: fin | H42: =SUM(H36:H38)-H40-H41 -> 41428
B52: Verano | C52: =(37771*42) -> 1586382 | D52: =26705*42 -> 1121610 | E52: =+D52/$C$60 -> 0.11783732 | F52: Verano | G52: =(37633*42) -> 1580586 | H52: =28578*42 -> 1200276 | I52: =+H52/$G$60 -> 0.12656445
B53: 1 | C53: =37771*30 -> 1133130 | D53: =29201*30 -> 876030 | E53: =+D53/$C$60+E52 -> 0.20987379 | F53: 1 | G53: =37633*30 -> 1128990 | H53: =33778*30 -> 1013340 | I53: =+H53/$G$60+I52 -> 0.23341723
B54: 2 | C54: =37771*30 -> 1133130 | D54: =29201*30 -> 876030 | E54: =+D54/$C$60+E53 -> 0.30191026 | F54: 2 | G54: =37633*30 -> 1128990 | H54: =33778*30 -> 1013340 | I54: =+H54/$G$60+I53 -> 0.34027
B55: 3 | C55: =37771*30 -> 1133130 | D55: =29201*30 -> 876030 | E55: =+D55/$C$60+E54 -> 0.39394673 | F55: 3 | G55: =37633*30 -> 1128990 | H55: =33778*30 -> 1013340 | I55: =+H55/$G$60+I54 -> 0.44712278
...

Sheet Mapa
M4: DEPARTAMENTO | N4: ZONA | O4: Rac. Día Refrigerios (en %) | P4: Rac. Día Comidas (en %) | Q4: Cantidad de Dependientes (en %)*
M5: Capital | N5: CAPITAL | O5: 70.284834 | P5: 79.460775 | Q5: 0.60391198
M6: Dto. de Alvear | N6: C | O6: 0 | P6: 0 | Q6: 0.0024449878
M7: Dto. de Bella Vista | N7: B | O7: 0.97977465 | P7: 0.69275417 | Q7: 0.014669927
M8: Dto. de Berón de Astrada | N8: C | O8: 0 | P8: 0.11233851 | Q8: 0.0048899756
M9: Dto. de Concepción | N9: B | O9: 0.48988733 | P9: 0.74892342 | Q9: 0.014669927
M10: Dto. de Curuzú Cuatiá | N10: B | O10: 2.204493 | P10: 0.59913874 | Q10: 0.017114914
M11: Dto. de Empedrado | N11: A | O11: 0.96227868 | P11: 0.48680022 | Q11: 0.014669927
M12: Dto. de Esquina | N12: A | O12: 1.5396459 | P12: 0.11233851 | Q12: 0.02200489
M13: Dto. de Goya | N13: A | O13: 5.8961439 | P13: 4.9241715 | Q13: 0.035452323
M14: Dto. de General Paz | N14: B | O14: 0.49688572 | P14: 0.71147725 | Q14: 0.012224939
M15: Dto. de Itatí | N15: C | O15: 0.73483099 | P15: 1.5165699 | Q15: 0.0097799511
M16: Dto. de Ituzaingó | N16: C | O16: 1.417174 | P16: 0.99232353 | Q16: 0.02200489
... M29: Dto. de Sauce | N29: B | O29: 0.34991952 | P29: 0.093615428 | Q29: 0.0048899756
O30: =SUM(O5:O29) -> 100 | P30: =SUM(P5:P29) -> 100 | Q30: =SUM(Q5:Q29) -> 1
N35: capital | O35: =SUMIF($N$5:$N$29,"capital",$Q$5:$Q$29) -> 0.60391198
N36: a | O36: =SUMIF($N$5:$N$29,"A",$Q$5:$Q$29) -> 0.11246944
N37: b | O37: =SUMIF($N$5:$N$29,"b",$Q$5:$Q$29) -> 0.14669927
N38: c | O38: =SUMIF($N$5:$N$29,"c",$Q$5:$Q$29) -> 0.13447433

Sheet PADRON CAP
C1: PADRON PLAN 1 AÑO 2026 - DIRECCION DE SEGURIDAD ALIMENTARIA (MINISTERIO DE DESARROLLO SOCIAL PROVINCIA DE CORRIENTES) - CAPITAL | J1: REFRIGERIOS | K1: comidas | L1: REFRIGERIOS | M1: comidas
A2: Cód. CERES | B2: Denominación CERES | C2: ZONA | D2: COMEDORES Y MERENDEROS | E2: DOMICILIO | F2: RESPONSABLE | G2: TIPO RECEPTOR | H2: BENEF | I2: Servicio
A3: ACC-0023 | B3: 3 de Abril (Nº 79) | C3: CAPITAL | D3: 3 DE ABRIL | E3: Barrio 3 de Abril - Cabo de Horno 3900 | F3: Benitez, Cristina Mabel | G3: ACCION SOCIAL | H3: =290-10-20 -> 260 | I3: COMIDAS
A4: ACC-0128 | B4: R - Asociación Civil La Amistad | C4: CAPITAL | D4: Asociacion Civil la Amistad | E4: Bº VILLA RAQUEL140 Viviendas, MZAG, Casa 8 por Saavedra e/ Cadiz y Andalucia | F4: Barberan, Elizabet | G4: ACCION SOCIAL | H4: =300-20 -> 280 | I4: REFRIGERIOS
A5: ACC-0115 | B5: C - Asociación Civil Misioneros de la Esperanza | C5: CAPITAL | D5: Asociacion civil misioneros de la esperanza | E5: Los Atacamas 2465 - Corrientes Capital | F5: Estiveros, Sandra | G5: ACCION SOCIAL | H5: 30 | I5: REFRIGERIOS
A6: ACC-0081 | B6: Asociación Fotos del Alma (Nº 24) | C6: CAPITAL | D6: Asociacion Fotos del Alma | E6: Bº Ex Aero Club Sarmiento 2985 - Nº 24 | F6: JOKMANOVICH, ROSSANA | G6: ACCION SOCIAL | H6: 20 | I6: COMIDAS
A7: ACC-0081 | B7: Asociación Fotos del Alma (Nº 24) | C7: CAPITAL | D7: Asociacion Fotos del Alma | E7: Bº Ex Aero Club Sarmiento 2985 - Nº 24 | F7: JOKMANOVICH, ROSSANA | G7: ACCION SOCIAL | H7: 30 | I7: REFRIGERIOS
A8: ACC-0123 | B8: Y - Barrio Río Paraná (Sembrando Sueños) | C8: CAPITAL | D8: Bº Rio Parana (SEMBRANDO SUEÑOS) | E8: Bº Río Parana Mocoretá S/N | F8: Sánchez, Estela | G8: ACCION SOCIAL | H8: =75+20+20 -> 115 | I8: REFRIGERIOS
A9: ACC-0086 | B9: C. D. Bosco Domingo y Laura (Nº 45) | C9: CAPITAL | D9: C. D. BOSCO DOMINGO Y LAURA | E9: Av. IV Centenario 3400 (Mendoza al Sur) | F9: SERVETTI, JUAN RAMON | G9: ACCION SOCIAL | H9: 60 | I9: COMIDAS
A10: ACC-0086 | B10: C. D. Bosco Domingo y Laura (Nº 45) | C10: CAPITAL | D10: C. D. BOSCO DOMINGO Y LAURA | E10: Av. IV Centenario 3400 (Mendoza al Sur) | F10: SERVETTI, JUAN RAMON | G10: ACCION SOCIAL | H10: 100 | I10: REFRIGERIOS
A11: ACC-0033 | B11: C.C.I. Caridi (Nº 11) | C11: CAPITAL | D11: C.C.I. Caridi Nº 11 | E11: Bº CARIDI - Ibañez y Suipacha (Nº 2200) | F11: Miranda,Lidia Beatriz | G11: ACCION SOCIAL | H11: =120+40-20 -> 140 | I11: REFRIGERIOS
A12: ACC-0033 | B12: C.C.I. Caridi (Nº 11) | C12: CAPITAL | D12: C.C.I. Caridi Nº 11 | E12: Bº CARIDI - Ibañez y Suipacha (Nº 2200) | F12: Miranda,Lidia Beatriz | G12: ACCION SOCIAL | H12: =230-30 -> 200 | I12: COMIDAS
A13: ACC-0034 | B13: C.C.I. Hectorcito (Nº 35) | C13: CAPITAL | D13: C.C.I. Hectorcito | E13: Bº MOLINA PUNTA 136 VIV. LOTE 18 | F13: NUÑEZ, ANTONIA REGINA | G13: ACCION SOCIAL | H13: =140-10 -> 130 | I13: REFRIGERIOS
A14: ACC-0034 | B14: C.C.I. Hectorcito (Nº 35) | C14: CAPITAL | D14: C.C.I. Hectorcito | E14: Bº MOLINA PUNTA 136 VIV. LOTE 18 | F14: NUÑEZ, ANTONIA REGINA | G14: ACCION SOCIAL | H14: =160-20 -> 140 | I14: COMIDAS
A15: ACC-0037 | B15: C.C.I. María Eva y Juan Manuel (Nº 16) | C15: CAPITAL | D15: C.C.I. M. Eva y J. Manuel | E15: Bº Dr. MONTAÑA - Conte y Lara | F15: MONTIEL, MARIA | G15: ACCION SOCIAL | H15: =50+20+20 -> 90 | I15: REFRIGERIOS
A16: ACC-0037 | B16: C.C.I. María Eva y Juan Manuel (Nº 16) | C16: CAPITAL | D16: C.C.I. M. Eva y J. Manuel | E16: Bº Dr. MONTAÑA - Conte y Lara | F16: MONTIEL, MARIA | G16: ACCION SOCIAL | H16: =70+30+20+30 -> 150 | I16: COMIDAS
A17: ACC-0035 | B17: C.C.I. María Auxiliadora (Nº 18) | C17: CAPITAL | D17: C.C.I. María Auxiliadora | E17: Bº Galván - Piragini Niveyro y Av. 3 de Abril/ detrás del sap Bº Galvan II (Nº 18) | F17: LOPEZ, NORMA-TOLEDO, ALEJANDRO | G17: ACCION SOCIAL | H17: 110 | I17: REFRIGERIOS
A18: ACC-0035 | B18: C.C.I. María Auxiliadora (Nº 18) | C18: CAPITAL | D18: C.C.I. María Auxiliadora | E18: Bº Galván - Piragini Niveyro y Av. 3 de Abril/ detrás del sap Bº Galvan II (Nº 18) | F18: LOPEZ, NORMA-TOLEDO, ALEJANDRO | G18: ACCION SOCIAL | H18: 250 | I18: COMIDAS
A19: ACC-000032 | B19: C.C.I. Paranacito (Nº 53)(A) | C19: CAPITAL | D19: C.C.I. Paranacito | E19: Bº RIO PARANA ALTA GRACIA Y CABO DE HORNO - Nº 53 | F19: BERNIE, JOSE LUIS | G19: ACCION SOCIAL | H19: 180 | I19: REFRIGERIOS
A20: ACC-000032 | B20: C.C.I. Paranacito (Nº 53)(A) | C20: CAPITAL | D20: C.C.I. Paranacito | E20: Bº RIO PARANA ALTA GRACIA Y CABO DE HORNO - Nº 53 | F20: BERNIE, JOSE LUIS | G20: ACCION SOCIAL | H20: 260 | I20: COMIDAS
A21: ACC-0031 | B21: C.C.I. Santa Rita (Nº 01) | C21: CAPITAL | D21: C.C.I. Santa Rita (Nº 01) | E21: Bº Apipé, Colodrero y Sicilia | F21: BOGADO, ROSARIO | G21: ACCION SOCIAL | H21: =70+20-10 -> 80 | I21: REFRIGERIOS
A22: ACC-0031 | B22: C.C.I. Santa Rita (Nº 01) | C22: CAPITAL | D22: C.C.I. Santa Rita (Nº 01) | E22: Bº Apipé, Colodrero y Sicilia | F22: BOGADO, ROSARIO | G22: ACCION SOCIAL | H22: =120+20-10 -> 130 | I22: COMIDAS
A23: MDS_07202409 | B23: C.P.C. Paloma de la Paz | C23: CAPITAL | D23: C.P.C. Paloma de la Paz | E23: Bº Ongay - Valdepeña y Güemes | F23: Ferreyra, Karina | G23: ACCION SOCIAL | H23: 50 | I23: REFRIGERIOS
A24: ACC-0028 | B24: Cabo de Hornos (Nº 81) | C24: CAPITAL | D24: CABO DE HORNOS | E24: Bº BAÑADO SUR - Cabo de Hornos 4000 | F24: ALDERETE, PABLO ALFREDO | G24: ACCION SOCIAL | H24: 70 | I24: COMIDAS
A25: ACC-0046 | B25: Capilla Santa Marta (Nº 69) | C25: CAPITAL | D25: CAPILLA SANTA MARTA | E25: Bº SANTA MARTA -J.R. Vidal 4100 - Nº 69 | F25: ALEGRE, CLAUDIA DEL PILAR | G25: ACCION SOCIAL | H25: 160 | I25: COMIDAS
A26: ACC-0046 | B26: Capilla Santa Marta (Nº 69) | C26: CAPITAL | D26: CAPILLA SANTA MARTA | E26: Bº SANTA MARTA -J.R. Vidal 4100 - Nº 69 | F26: ALEGRE, CLAUDIA DEL PILAR | G26: ACCION SOCIAL | H26: 160 | I26: REFRIGERIOS
A27: MDS_ACC_2617 | B27: Capilla Guadalupe | C27: CAPITAL | D27: Capilla Guadalupe | E27: Los Tehuelches y Matacos - Bº San Antonio Oeste (Tunuyán 3376) | F27: Navarro, Tomasa | G27: ACCION SOCIAL | H27: 40 | I27: REFRIGERIOS
A28: SDH-CE-10 | B28: Capilla Roselo | C28: CAPITAL | D28: Capilla Roselo | E28: B° Quintana - Capital Nicaragua, Sta. Teresa de Calcuta y Suecia (Cel. 3794664602) | F28: Giménez, Florentino | G28: ACCION SOCIAL | H28: =80-20-30 -> 30 | I28: REFRIGERIOS
A29: ACC-0071 | B29: Capilla San Ignacio de Loyola (Nº 72) | C29: CAPITAL | D29: Capilla San Ignacio de Loyola (Nº 72) | E29: Bª LOMAS mza 6 lote 37 | F29: CERDAN, CELESTINA | G29: ACCION SOCIAL | H29: =100-20 -> 80 | I29: COMIDAS
A30: ACC-0067 | B30: Capilla San José (Nº 50) | C30: CAPITAL | D30: Capilla San José | E30: Bº QUINTA FERRE ZACARIAS SANCHEZ S/N - Nº 50 | F30: CORREA, ALFREDO SIMON | G30: ACCION SOCIAL | H30: 70 | I30: REFRIGERIOS
A31: ACC-0067 | B31: Capilla San José (Nº 50) | C31: CAPITAL | D31: Capilla San José | E31: Bº QUINTA FERRE ZACARIAS SANCHEZ S/N - Nº 50 | F31: CORREA, ALFREDO SIMON | G31: ACCION SOCIAL | H31: 180 | I31: COMIDAS
A32: ACC-0118 | B32: Z - Capilla Virgen de Itatí | C32: CAPITAL | D32: Capilla Virgen de Itati | E32: Bº ITATI Amado Bonpland Nº 395 Sec 3 Casa 32 | F32: Gómez, Oscar | G32: ACCION SOCIAL | H32: =180-20 -> 160 | I32: REFRIGERIOS
A33: ACC-0112 | B33: H - Capilla Virgen de Luján | C33: CAPITAL | D33: Capilla Virgen de Lujan | E33: Bª PONCE VIEJO - Vazquez esquina Moresi | F33: Gómez, María Mercedes. DNI: 20676211 | G33: ACCION SOCIAL | H33: 80 | I33: REFRIGERIOS
A34: ACC-0069 | B34: Capilla Virgen del Carmen (Nº 19) | C34: CAPITAL | D34: Capilla Virgen del Carmen (Nº 19) | E34: Bº GALVAN Alberdi 2979 - Nº 19 | F34: YEDRO, ELVA ITATI | G34: ACCION SOCIAL | H34: =120-20 -> 100 | I34: REFRIGERIOS
A35: ACC-0069 | B35: Capilla Virgen del Carmen (Nº 19) | C35: CAPITAL | D35: Capilla Virgen del Carmen (Nº 19) | E35: Bº GALVAN Alberdi 2979 - Nº 19 | F35: YEDRO, ELVA ITATI | G35: ACCION SOCIAL | H35: =200-20-20 -> 160 | I35: COMIDAS
A36: ACC -0050 | B36: Merendero "Carita de Ángel" | C36: CAPITAL | D36: Carita de Ángel | E36: Bº Virgen de los Dolores mza 2 casa 2 | F36: López Miranda, Ailin Melanie Milagros | G36: ACCION SOCIAL | H36: 50 | I36: REFRIGERIOS
A37: ACC-0049 | B37: Caritas Sucias (Nº 44) | C37: CAPITAL | D37: Caritas Sucias (Nº 44) | E37: Bº PLACIDO MARTINEZ - Bonpland sec E casa 22 | F37: VALLEJOS, RITA ISABEL | G37: ACCION SOCIAL | H37: =60+20-10 -> 70 | I37: COMIDAS
A38: ACC-0049 | B38: Caritas Sucias (Nº 44) | C38: CAPITAL | D38: Caritas Sucias (Nº 44) | E38: Bº PLACIDO MARTINEZ - Bonpland sec E casa 22 | F38: VALLEJOS, RITA ISABEL | G38: ACCION SOCIAL | H38: =130+20-20-10 -> 120 | I38: REFRIGERIOS
A39: ACC-0054 | B39: Centro Atención Personas Especiales (Nº 4 - CAPES SONUA) | C39: CAPITAL | D39: Centro At. Personas Esp.(CAPES SONUA) | E39: Bº BELGRANO Almte. Brown y EEUU Nº 4 | F39: Díaz, Leticia - Ramirez Mirta | G39: ACCION SOCIAL | H39: 100 | I39: REFRIGERIOS
A40: ACC-0054 | B40: Centro Atención Personas Especiales (Nº 4 - CAPES SONUA) | C40: CAPITAL | D40: Centro At. Personas Esp.(CAPES SONUA) | E40: Bº BELGRANO Almte. Brown y EEUU Nº 4 | F40: Díaz, Leticia - Ramirez Mirta | G40: ACCION SOCIAL | H40: 100 | I40: COMIDAS
...

Sheet PADRON INTERIOR
A1: PADRON PLAN 1 AÑO 2026 - DIRECCION DE SEGURIDAD ALIMENTARIA (MINISTERIO DE DESARROLLO SOCIAL PROVINCIA DE CORRIENTES) - INTERIOR | M1: refrigerios | N1: comidas
A2: ZONA | B2: CENTRO DE DISTRIBUCIÓN | C2: CENTRO DE ENTREGA | D2: DIRECCIÓN | E2: TELEFONO | F2: DEPARTAMENTO | G2: LOCALIDAD | H2: BENEF | I2: ORGANISMO | J2: DETALLE SERV. | K2: st | L2: Org.II
A3: C | B3: C.P.F. Nº 1 San Jose Obrero | C3: C.P.F. Nº 1 San Jose Obrero | D3: Larrea y Suipacha | E3: Nora Ester Segovia (03772 401412) | F3: Dto. de Alvear | G3: Alvear | H3: 75 | I3: MIN. Y FLIA. | J3: REFRIGERIOS
A4: C | B4: C.P.F. Nº 1 San Jose Obrero | C4: C.P.F. Nº 1 San Jose Obrero | D4: Larrea y Suipacha | E4: Nora Ester Segovia (03772 401412) | F4: Dto. de Alvear | G4: Alvear | H4: 60 | I4: MIN. Y FLIA. | J4: COMIDAS
A5: A | B5: C.I.C. de la localidad de Bella Vista | C5: C.I.C. de la localidad de Bella Vista | D5: 25 de Mayo casi Charcas S/N | E5: 3777-543472 (Carolina Zalazar) | F5: Dto. de Bella Vista | G5: Bella Vista | H5: 100 | I5: ACCION SOCIAL | J5: COMIDAS
A6: A | B6: Gurisito Costero | C6: C.P.M. Nº 11 Gurisito Costero | D6: Belgrano y Costanera Zona Ribereña, El Carrizal | E6: 3777-554922 (Erika Carrasco) | F6: Dto. de Bella Vista | G6: Bella Vista | H6: 115 | I6: MIN. Y FLIA. | J6: COMIDAS
A7: A | B7: Gurisito Costero | C7: C.P.M. Nº 11 Gurisito Costero | D7: Belgrano y Costanera Zona Ribereña, El Carrizal | E7: 3777-554922 (Erika Carrasco) | F7: Dto. de Bella Vista | G7: Bella Vista | H7: 110 | I7: MIN. Y FLIA. | J7: REFRIGERIOS
A8: A | B8: Gurisito Costero | C8: Cong. Cristiana B. Vista | D8: Belgrano y Costanera Zona Ribereña, El Carrizal | E8: 3777-479009 (Graciela Lujan Gek) | F8: Dto. de Bella Vista | G8: Bella Vista | H8: 60 | I8: MIN. Y FLIA. | J8: COMIDAS
A9: A | B9: Gurisito Costero | C9: H.A. Nuevo Amanecer | D9: Estrada 66 - Bella Vista | E9: 3777-304595 (Soto Sandra Leticia) | F9: Dto. de Bella Vista | G9: Bella Vista | H9: 25 | I9: MIN. Y FLIA. | J9: COMIDAS
A10: A | B10: Gurisito Costero | C10: H.A. Nuevo Amanecer | D10: Estrada 66 - Bella Vista | E10: 3777-304595 (Soto Sandra Leticia) | F10: Dto. de Bella Vista | G10: Bella Vista | H10: 30 | I10: MIN. Y FLIA. | J10: REFRIGERIOS
A11: A | B11: Gurisito Costero | C11: J.M. Sagrado Corazón de Jesús | D11: Bº Los Pinos | E11: 3777-310761 (Fany Rolon) | F11: Dto. de Bella Vista | G11: Bella Vista | H11: 60 | I11: MIN. Y FLIA. | J11: COMIDAS
A12: A | B12: Gurisito Costero | C12: J.M. Sagrado Corazón de Jesús | D12: Bº Los Pinos | E12: 3777-310761 (Fany Rolon) | F12: Dto. de Bella Vista | G12: Bella Vista | H12: 90 | I12: MIN. Y FLIA. | J12: REFRIGERIOS
A13: A | B13: Liga Bellavistense de Fútbol (Para 8 Clubes) | C13: Liga Bellavistense de Fútbol (Para 8 Clubes) | D13: Sucre y Montevideo - Bella Vista | E13: 3777-609978 (Juan Insaurralde) | F13: Dto. de Bella Vista | G13: Bella Vista | H13: 250 | I13: ACCION SOCIAL | J13: REFRIGERIOS
A14: C | B14: C.P.M. Nº 22 Pago Redondo | C14: C.P.M. Nº 22 Pago Redondo | D14: Ex Mercado de Abasto | E14: 3794652143 (Celida Noemí Voulquin) | F14: Dto. de Berón de Astrada | G14: Berón de Astrada | H14: 35 | I14: MIN. Y FLIA. | J14: COMIDAS
... A18: A | B18: Fruto Verde | C18: Fruto Verde | D18: Riachuelo - 11 Leones (Zona Rural) | E18: 3794-273201 (Sandra Correa) | F18: Dto. de Capital | G18: Riachuelo | H18: 50 | I18: ACCION SOCIAL | J18: REFRIGERIOS
A19: A | B19: G - Los Chiquilines | C19: G - Los Chiquilines | D19: Riachuelo Pueblo Echazarreta 103 - Dpto. de Empedrado | E19: 3794-153881 (Lidia Esther Villan) | F19: Dto. de Capital | G19: Riachuelo | H19: =90+20+25 -> 135 | I19: ACCION SOCIAL | J19: COMIDAS
A20: A | B20: G - Los Chiquilines | C20: G - Los Chiquilines | D20: Riachuelo Pueblo Echazarreta 103 - Dpto. de Empedrado | E20: 3794-153881 (Lidia Esther Villan) | F20: Dto. de Capital | G20: Riachuelo | H20: =20+20 -> 40 | I20: ACCION SOCIAL | J20: REFRIGERIOS
A21: A | B21: Jesús Misericordioso (Nº 73) | C21: Jesús Misericordioso (Nº 73) | D21: Riachuelo - Rincón Roa Fopar | E21: 3794-631346 (Claudia Roa) | F21: Dto. de Capital | G21: Riachuelo | H21: 50 | I21: ACCION SOCIAL | J21: COMIDAS
A22: A | B22: Jesús Misericordioso (Nº 73) | C22: Jesús Misericordioso (Nº 73) | D22: Riachuelo - Rincón Roa Fopar | E22: 3794-631346 (Claudia Roa) | F22: Dto. de Capital | G22: Riachuelo | H22: 50 | I22: ACCION SOCIAL | J22: REFRIGERIOS
A23: A | B23: La Gurisada | C23: La Gurisada | D23: Km. 34 / Rta. 12 - El Sombrero (Empedrado) | E23: 3794-002572 (Graciela González) | F23: Dto. de Capital | G23: Riachuelo | H23: =130+20 -> 150 | I23: ACCION SOCIAL | J23: COMIDAS
A24: A | B24: La Gurisada | C24: La Gurisada | D24: Km. 34 / Rta. 12 - El Sombrero (Empedrado) | E24: 3794-002572 (Graciela González) | F24: Dto. de Capital | G24: Riachuelo | H24: 50 | I24: ACCION SOCIAL | J24: REFRIGERIOS
A25: A | B25: Riachuelo (Nº 76) | C25: Riachuelo (Nº 76) | D25: Riachuelo - 11 Leones / Cuarta Sección - Domínguez Marta D.N.I. Nº: 21.870.412. | E25: 3795-153281 (Marta Dominguez) | F25: Dto. de Capital | G25: Riachuelo | H25: 65 | I25: ACCION SOCIAL | J25: COMIDAS
A26: A | B26: Riachuelo (Nº 76) | C26: Riachuelo (Nº 76) | D26: Riachuelo - 11 Leones / Cuarta Sección - Domínguez Marta D.N.I. Nº: 21.870.412. | E26: 3795-153281 (Marta Dominguez) | F26: Dto. de Capital | G26: Riachuelo | H26: =65+20 -> 85 | I26: ACCION SOCIAL | J26: REFRIGERIOS
A27: A | B27: Santa Margarita | C27: Santa Margarita | D27: Riachuelo - Barrio Sta. Margarita, Los Lapachos | E27: 3794-566852 (Celia Beatriz Maidana) | F27: Dto. de Capital | G27: Riachuelo | H27: =50+25+45 -> 120 | I27: ACCION SOCIAL | J27: COMIDAS
A28: A | B28: Santa Margarita | C28: Santa Margarita | D28: Riachuelo - Barrio Sta. Margarita, Los Lapachos | E28: 3794-566852 (Celia Beatriz Maidana) | F28: Dto. de Capital | G28: Riachuelo | H28: =60+25+25 -> 110 | I28: ACCION SOCIAL | J28: REFRIGERIOS
A29: B | B29: Merendero Carita Feliz | C29: Merendero Carita Feliz | D29: Bº San Martín, bajar por Ruta Nac. 118 km 48 (2º Entrada a Tabay - Ermita de la Virgen de Luján - Galpones verdes de Coqui Palacio) Zunilda Palacio | E29: 3782-486684 (Zunilda Palacio ) | F29: Dto. de Concepción | G29: Tabay | H29: =20+20 -> 40 | I29: ACCION SOCIAL | J29: REFRIGERIOS
A30: B | B30: Merendero Rayo de Luz | C30: Merendero Rayo de Luz | D30: Ruta Nac. 118 km 49 (cerca Esc. Nº 211 - Adolfo Alvarez | E30: 3794-347342 (Andrea Edith Sanchez) | F30: Dto. de Concepción | G30: Tabay | H30: 50 | I30: ACCION SOCIAL | J30: REFRIGERIOS
A31: B | B31: Centro Nº 3 Virgen de Itatí | C31: Centro Nº 3 Virgen de Itatí | D31: Calle Curupy y San Martin- Colonia Tatacuá - (Cel. 3794075879 - Fernández) | E31: 3794-075879 (Carolina Fernández) | F31: Dto. de Concepción | G31: Concepción | H31: 150 | I31: MIN. Y FLIA. | J31: COMIDAS
A32: B | B32: J.M. Adela Feris de Romero | C32: J.M. Adela Feris de Romero | D32: Independencia 547 | E32: 3795-160547 (Ramona Mercedes Cardozo) | F32: Dto. de Concepción | G32: Concepción | H32: 45 | I32: MIN. Y FLIA. | J32: COMIDAS
A33: B | B33: J.M. Adela Feris de Romero | C33: J.M. Adela Feris de Romero | D33: Independencia 547 | E33: 3795-160547 (Ramona Mercedes Cardozo) | F33: Dto. de Concepción | G33: Concepción | H33: 40 | I33: MIN. Y FLIA. | J33: REFRIGERIOS
A34: B | B34: C.I.P.I. Nº 4 "Maria de Nazareth" | C34: C.I.P.I. Nº 4 "Maria de Nazareth" | D34: Detrás de la Intendencia de Santa Rosa | E34: 3794-204031 (Vanina Pavón) | F34: Dto. de Concepción | G34: Santa Rosa | H34: 45 | I34: MIN. Y FLIA. | J34: COMIDAS
A35: B | B35: C.I.P.I. Nº 4 "Maria de Nazareth" | C35: C.I.P.I. Nº 4 "Maria de Nazareth" | D35: Detrás de la Intendencia de Santa Rosa | E35: 3794-204031 (Vanina Pavón) | F35: Dto. de Concepción | G35: Santa Rosa | H35: 60 | I35: MIN. Y FLIA. | J35: REFRIGERIOS
A36: B | B36: Comedor Capilla San Cayetano | C36: Comedor Capilla San Cayetano | D36: Juan Bautista Cabral 045 | E36: 3782-525745 (Marcelo Otazo) - 3782-510835 (Lourdes Pereyra) | F36: Dto. de Concepción | G36: Santa Rosa | H36: 50 | I36: ACCION SOCIAL | J36: REFRIGERIOS
A37: B | B37: Comedor Capilla San Cayetano | C37: Comedor Capilla San Cayetano | D37: Juan Bautista Cabral 045 | E37: 3782-525745 (Marcelo Otazo) - 3782-510835 (Lourdes Pereyra) | F37: Dto. de Concepción | G37: Santa Rosa | H37: 50 | I37: ACCION SOCIAL | J37: COMIDAS
A38: B | B38: C.I.C. Curuzú Cuatiá | C38: C.I.C. Curuzú Cuatiá | D38: Sarmiento y Deán Funes | E38: 3774-630197 (Ana clara Jauregui) | F38: Dto. de Curuzú Cuatiá | G38: Curuzú Cuatiá | H38: 100 | I38: ACCION SOCIAL | J38: COMIDAS
A39: B | B39: C.I.C. Curuzú Cuatiá | C39: C.I.C. Curuzú Cuatiá | D39: Sarmiento y Deán Funes | E39: 3774-630197 (Ana clara Jauregui) | F39: Dto. de Curuzú Cuatiá | G39: Curuzú Cuatiá | H39: 270 | I39: ACCION SOCIAL | J39: REFRIGERIOS
A40: B | B40: Club Atlético Santa Rosa | C40: Club Atlético Santa Rosa | D40: Gral. Ramírez N° 832 | E40: 3774-402063 (Ariel Vallejos) | F40: Dto. de Curuzú Cuatiá | G40: Curuzú Cuatiá | H40: =60-30 -> 30 | I40: ACCION SOCIAL | J40: COMIDAS
A41: B | B41: Club Atlético Santa Rosa | C41: Club Atlético Santa Rosa | D41: Gral. Ramírez N° 832 | E41: 3774-402063 (Ariel Vallejos) | F41: Dto. de Curuzú Cuatiá | G41: Curuzú Cuatiá | H41: =150-20 -> 130 | I41: ACCION SOCIAL | J41: REFRIGERIOS
A42: B | B42: H.A. Adelina B. de Ezcurra | C42: H.A. Adelina B. de Ezcurra | D42: Av. España 244 | E42: 3774-465885 (Carmen Marticorena) | F42: Dto. de Curuzú Cuatiá | G42: Curuzú Cuatiá | H42: 30 | I42: MIN. Y FLIA. | J42: COMIDAS
A43: B | B43: H.A. Adelina B. de Ezcurra | C43: H.A. Adelina B. de Ezcurra | D43: Av. España 244 | E43: 3774-465885 (Carmen Marticorena) | F43: Dto. de Curuzú Cuatiá | G43: Curuzú Cuatiá | H43: =70 -> 70 | I43: MIN. Y FLIA. | J43: REFRIGERIOS
...

Sheet PRESUPUESTO
B2: RAC. DÍA
B3: COMIDA | C3: REFRIGERIOS | I3: COBERTURA
B4: 29226 | C4: 33838 | J4: CANT. DÍAS
I5: PLAN VERANO | J5: 42
I6: PALN 1 | J6: 30
B7: PRECIO UNITARIO POR RAC. | I7: PLAN 2 | J7: 30
B8: 1600 | I8: PLAN 3 | J8: 30
I9: PLAN 4 | J9: 30
B10: PRESUPUESTO DIARIO | I10: PLAN 5 | J10: 30
B11: =B4*B8 -> 46761600 | C11: =C4*B8 -> 54140800 | I11: PLAN 6 | J11: 30
B12: TOTAL DIARIO | I12: PLAN 7 | J12: 30
B13: =SUM(B11+C11) -> 100902400 | I13: TOTAL
I14: DÍAS | J14: =SUM(J5:J12) -> 252
B15: TOTAL 30 DIAS
B16: =SUM(B13*30) -> 3027072000
B18: TOTAL 252 DÍAS (ANUAL)
B19: =SUM(B13*252) -> 25427404800
